function callWithErrorHandling(fn, instance, type, args) {
    let res;
    try {
      res = args ? fn(...args) : fn();
    } catch (err) {
      handleError(err, instance, type);
    }
    return res;
  }