function handleErrors(fn) {
  return async function (req, res, next) {
    try {
      return await fn(req, res);
    } catch (x) {
      next(x);
    }
  };
}